Workbook

Sheet Summary
C2: Pidilite Industries DCF
C3: Complete base case | Actuals through 31 March 2026 | Forecast FY:27–FY:31 | ₹ crore
C6: Historical snapshot
C7: Metric | D7: FY:22 | E7: FY:23 | F7: FY:24 | G7: FY:25 | H7: FY:26
C8: Revenue from operations | D8: ='P&L'!D7 -> 9920.96 | E8: ='P&L'!E7 -> 11799.1 | F8: ='P&L'!F7 -> 12382.99 | G8: ='P&L'!G7 -> 13140.31 | H8: ='P&L'!H7 -> 14600.83
C9: YoY revenue growth | D9: n.a. | E9: ='P&L'!E8 -> 0.18931031 | F9: ='P&L'!F8 -> 0.049485978 | G9: ='P&L'!G8 -> 0.061158089 | H9: ='P&L'!H8 -> 0.11114806
C10: Operating EBITDA | D10: ='P&L'!D37 -> 1847.29 | E10: ='P&L'!E37 -> 1984.37 | F10: ='P&L'!F37 -> 2707.27 | G10: ='P&L'!G37 -> 3012.51 | H10: ='P&L'!H37 -> 3519
C11: EBITDA margin | D11: ='P&L'!D38 -> 0.18620073 | E11: ='P&L'!E38 -> 0.16817978 | F11: ='P&L'!F38 -> 0.21862813 | G11: ='P&L'!G38 -> 0.22925715 | H11: ='P&L'!H38 -> 0.2410137
C12: Operating EBIT | D12: ='P&L'!D39 -> 1607.68 | E12: ='P&L'!E39 -> 1714.63 | F12: ='P&L'!F39 -> 2366.61 | G12: ='P&L'!G39 -> 2654.03 | H12: ='P&L'!H39 -> 3124.29
C13: Profit for the year | D13: ='P&L'!D30 -> 1206.76 | E13: ='P&L'!E30 -> 1288.87 | F13: ='P&L'!F30 -> 1747.42 | G13: ='P&L'!G30 -> 2096.17 | H13: ='P&L'!H30 -> 2470.72
C14: Effective tax rate | D14: ='P&L'!D29 -> 0.2522153 | E14: ='P&L'!E29 -> 0.25206588 | F14: ='P&L'!F29 -> 0.26558934 | G14: ='P&L'!G29 -> 0.25738832 | H14: ='P&L'!H29 -> 0.25584533
C15: Cash flow-based historical FCFF | D15: =FCF!D12 -> 612.09678 | E15: =FCF!E12 -> 1087.8516 | F15: =FCF!F12 -> 2202.9045 | G15: =FCF!G12 -> 1871.6805 | H15: =FCF!H12 -> 2276.0281
C16: FCFF margin | D16: =FCF!D13 -> 0.061697334 | E16: =FCF!E13 -> 0.092197844 | F16: =FCF!F13 -> 0.17789762 | G16: =FCF!G13 -> 0.14243808 | H16: =FCF!H13 -> 0.15588347
C17: Net cash and investments (carrying value) | D17: =FCF!D30 -> 337.29 | E17: =FCF!E30 -> 721.87 | F17: =FCF!F30 -> 2280.89 | G17: =FCF!G30 -> 3333.32 | H17: =FCF!H30 -> 4065.08
C19: DCF status
C20: Enterprise value | H20: =DCF!D18 -> 38133.746
C21: Selected net financial assets | H21: =DCF!D19 -> 4146.42
C22: Equity value | H22: =DCF!D20 -> 42280.166
C23: Implied value per share | H23: =DCF!D22 -> 414.52836
C24: Reason | D24: Pale-yellow assumptions are editable, and the model recalculates automatically.

Sheet Assumptions
C2: Assumptions
C3: Editable base-case operating drivers and market-reference WACC build
C6: Model controls
C7: Valuation date | D7: 46112
C8: Currency and scale | D8: ₹ crore
C9: Valuation method | D9: FCFF DCF
C10: Forecast horizon | D10: 5
C11: Terminal value method | D11: Perpetuity growth
C12: Case selected | D12: Base
C14: Forecast inputs
C15: Driver | D15: FY:27 | E15: FY:28 | F15: FY:29 | G15: FY:30 | H15: FY:31
C16: Revenue growth | D16: 0.105 | E16: 0.1 | F16: 0.095 | G16: 0.09 | H16: 0.085
C17: EBITDA margin | D17: 0.243 | E17: 0.245 | F17: 0.247 | G17: 0.248 | H17: 0.25
C18: D&A as % of revenue | D18: 0.027 | E18: 0.027 | F18: 0.027 | G18: 0.027 | H18: 0.027
C19: Effective tax rate | D19: 0.256 | E19: 0.256 | F19: 0.256 | G19: 0.256 | H19: 0.256
C20: Capex as % of revenue | D20: 0.04 | E20: 0.04 | F20: 0.039 | G20: 0.038 | H20: 0.038
C21: DSO | D21: 54 | E21: 53 | F21: 52 | G21: 51 | H21: 50
C22: DIO | D22: 98 | E22: 97 | F22: 96 | G22: 95 | H22: 95
C23: DPO | D23: 86 | E23: 86 | F23: 86 | G23: 86 | H23: 86
C24: WACC | D24: =$D$48 -> 0.1201394 | E24: =$D$48 -> 0.1201394 | F24: =$D$48 -> 0.1201394 | G24: =$D$48 -> 0.1201394 | H24: =$D$48 -> 0.1201394
C25: Terminal growth | D25: =$D$49 -> 0.05 | E25: =$D$49 -> 0.05 | F25: =$D$49 -> 0.05 | G25: =$D$49 -> 0.05 | H25: =$D$49 -> 0.05
C27: Pale-yellow cells are editable base-case assumptions; forecast and valuation formulas update automatically.
C29: WACC and terminal-value build
C30: Input | D30: Value | E30: Source / rationale
C31: India 10-year government-bond yield | D31: 0.0684 | E31: FRED, India long-term government-bond yield, March 2026: 6.84% | https://fred.stlouisfed.org/series/IRLTLT01INM156N
C32: India total equity risk premium | D32: 0.0708 | E32: Damodaran country-risk table, 5 Jan 2026: India total ERP 7.08% | https://pages.stern.nyu.edu/adamodar/New_Home_Page/datafile/ctryprem.html
C33: Household-products unlevered beta | D33: 0.72 | E33: Damodaran US sector betas, Jan 2026: Household Products unlevered beta 0.72 | https://pages.stern.nyu.edu/~adamodar/New_Home_Page/datafile/Betas.html
C34: Specialty-chemicals unlevered beta | D34: 0.79 | E34: Damodaran US sector betas, Jan 2026: Specialty Chemicals unlevered beta 0.79 | https://pages.stern.nyu.edu/~adamodar/New_Home_Page/datafile/Betas.html
C35: Consumer & Bazaar business mix | D35: 0.816 | E35: FY:26 management business review: Consumer & Bazaar represented 81.6% of standalone sales
C36: B2B and other business mix | D36: 0.184 | E36: FY:26 management business review: B2B represented 18.0%; residual 0.4% included here
C37: Selected bottom-up beta | D37: =D33*D35+D34*D36 -> 0.73288 | E37: Revenue-mix-weighted bottom-up unlevered beta; leverage is immaterial
C38: Cost of equity | D38: =D31+D37*D32 -> 0.1202879 | E38: CAPM: risk-free rate plus selected beta multiplied by India total ERP
C39: Pre-tax cost of debt | D39: 0.085 | E39: Selected within the FY:26 disclosed borrowing-rate range; applied to debt and leases
C40: Effective tax rate | D40: ='P&L'!H29 -> 0.25584533 | E40: FY:26 consolidated effective tax rate
C41: After-tax cost of debt | D41: =D39*(1-D40) -> 0.063253147 | E41: Pre-tax debt cost after the effective-tax shield
C42: Market-price reference per share | D42: 1566.9 | E42: Market reference at 11 Sep 2026; used only for capital weights and comparison
C43: Diluted shares (crore) | D43: ='Valuation Bridge'!E34 -> 101.99584 | E43: FY:26 reported diluted weighted-average denominator, bonus-adjusted
C44: Market equity value | D44: =D42*D43 -> 159817.27 | E44: Market-price reference multiplied by diluted shares
C45: Debt and lease liabilities | D45: ='Valuation Bridge'!E24 -> 417.21 | E45: FY:26 current borrowings and lease liabilities
C46: Equity weight | D46: =D44/(D44+D45) -> 0.99739625 | E46: Market-value capital weight
...

Sheet Forecast
C2: Base-case FCFF forecast
C3: Formula-driven operating forecast | FY:26 actual and FY:27–FY:31 estimates | ₹ crore
C5: Metric | D5: FY:26A | E5: FY:27E | F5: FY:28E | G5: FY:29E | H5: FY:30E | I5: FY:31E
C6: Operating forecast
C7: Revenue from operations | D7: ='P&L'!H7 -> 14600.83 | E7: =D7*(1+Assumptions!D16) -> 16133.917 | F7: =E7*(1+Assumptions!E16) -> 17747.309 | G7: =F7*(1+Assumptions!F16) -> 19433.303 | H7: =G7*(1+Assumptions!G16) -> 21182.3 | I7: =H7*(1+Assumptions!H16) -> 22982.796
C8: Revenue growth | D8: ='P&L'!H8 -> 0.11114806 | E8: =Assumptions!D16 -> 0.105 | F8: =Assumptions!E16 -> 0.1 | G8: =Assumptions!F16 -> 0.095 | H8: =Assumptions!G16 -> 0.09 | I8: =Assumptions!H16 -> 0.085
C9: EBITDA margin | D9: ='P&L'!H38 -> 0.2410137 | E9: =Assumptions!D17 -> 0.243 | F9: =Assumptions!E17 -> 0.245 | G9: =Assumptions!F17 -> 0.247 | H9: =Assumptions!G17 -> 0.248 | I9: =Assumptions!H17 -> 0.25
C10: Operating EBITDA | D10: ='P&L'!H37 -> 3519 | E10: =E7*E9 -> 3920.5419 | F10: =F7*F9 -> 4348.0907 | G10: =G7*G9 -> 4800.0259 | H10: =H7*H9 -> 5253.2105 | I10: =I7*I9 -> 5745.699
C11: D&A as % of revenue | D11: =-'P&L'!H17/'P&L'!H7 -> 0.027033395 | E11: =Assumptions!D18 -> 0.027 | F11: =Assumptions!E18 -> 0.027 | G11: =Assumptions!F18 -> 0.027 | H11: =Assumptions!G18 -> 0.027 | I11: =Assumptions!H18 -> 0.027
C12: D&A | D12: =-'P&L'!H17 -> 394.71 | E12: =E7*E11 -> 435.61576 | F12: =F7*F11 -> 479.17734 | G12: =G7*G11 -> 524.69919 | H12: =H7*H11 -> 571.92211 | I12: =I7*I11 -> 620.53549
C13: Operating EBIT | D13: ='P&L'!H39 -> 3124.29 | E13: =E10-E12 -> 3484.9261 | F13: =F10-F12 -> 3868.9133 | G13: =G10-G12 -> 4275.3267 | H13: =H10-H12 -> 4681.2884 | I13: =I10-I12 -> 5125.1635
C14: EBIT margin | D14: ='P&L'!H40 -> 0.2139803 | E14: =E13/E7 -> 0.216 | F14: =F13/F7 -> 0.218 | G14: =G13/G7 -> 0.22 | H14: =H13/H7 -> 0.221 | I14: =I13/I7 -> 0.223
C15: Effective tax rate | D15: ='P&L'!H29 -> 0.25584533 | E15: =Assumptions!D19 -> 0.256 | F15: =Assumptions!E19 -> 0.256 | G15: =Assumptions!F19 -> 0.256 | H15: =Assumptions!G19 -> 0.256 | I15: =Assumptions!H19 -> 0.256
C16: NOPAT | D16: =D13*(1-D15) -> 2324.955 | E16: =E13*(1-E15) -> 2592.785 | F16: =F13*(1-F15) -> 2878.4715 | G16: =G13*(1-G15) -> 3180.8431 | H16: =H13*(1-H15) -> 3482.8786 | I16: =I13*(1-I15) -> 3813.1217
C18: Operating working capital
C19: Days sales outstanding | D19: =FCF!H23 -> 54.5244 | E19: =Assumptions!D21 -> 54 | F19: =Assumptions!E21 -> 53 | G19: =Assumptions!F21 -> 52 | H19: =Assumptions!G21 -> 51 | I19: =Assumptions!H21 -> 50
C20: Days inventory outstanding | D20: =FCF!H24 -> 97.737573 | E20: =Assumptions!D22 -> 98 | F20: =Assumptions!E22 -> 97 | G20: =Assumptions!F22 -> 96 | H20: =Assumptions!G22 -> 95 | I20: =Assumptions!H22 -> 95
C21: Days payable outstanding | D21: =FCF!H25 -> 86.433291 | E21: =Assumptions!D23 -> 86 | F21: =Assumptions!E23 -> 86 | G21: =Assumptions!F23 -> 86 | H21: =Assumptions!G23 -> 86 | I21: =Assumptions!H23 -> 86
C22: Direct cost base as % of revenue | D22: =FCF!H22/'P&L'!H7 -> 0.44443021 | E22: =$D$22 -> 0.44443021 | F22: =$D$22 -> 0.44443021 | G22: =$D$22 -> 0.44443021 | H22: =$D$22 -> 0.44443021 | I22: =$D$22 -> 0.44443021
C23: Direct cost base | D23: =FCF!H22 -> 6489.05 | E23: =E7*E22 -> 7170.4003 | F23: =F7*F22 -> 7887.4403 | G23: =G7*G22 -> 8636.7471 | H23: =H7*H22 -> 9414.0543 | I23: =I7*I22 -> 10214.249
C24: Trade receivables | D24: ='Balance Sheet'!H24 -> 2181.1 | E24: =E7*E19/365 -> 2386.9357 | F24: =F7*F19/365 -> 2577.0065 | G24: =G7*G19/365 -> 2768.5802 | H24: =H7*H19/365 -> 2959.7187 | I24: =I7*I19/365 -> 3148.3282
C25: Inventories | D25: ='Balance Sheet'!H22 -> 1737.6 | E25: =E23*E20/365 -> 1925.2034 | F25: =F23*F20/365 -> 2096.1143 | G25: =G23*G20/365 -> 2271.5828 | H25: =H23*H20/365 -> 2450.2333 | I25: =I23*I20/365 -> 2658.5032
C26: Trade payables | D26: ='Balance Sheet'!H60 -> 1536.63 | E26: =E23*E21/365 -> 1689.4642 | F26: =F23*F21/365 -> 1858.4106 | G26: =G23*G21/365 -> 2034.9596 | H26: =H23*H21/365 -> 2218.106 | I26: =I23*I21/365 -> 2406.645
C27: Core operating net working capital | D27: =D24+D25-D26 -> 2382.07 | E27: =E24+E25-E26 -> 2622.6749 | F27: =F24+F25-F26 -> 2814.7102 | G27: =G24+G25-G26 -> 3005.2034 | H27: =H24+H25-H26 -> 3191.8461 | I27: =I24+I25-I26 -> 3400.1864
C28: Change in core operating net working capital | D28: =FCF!H20 -> 275.88 | E28: =E27-D27 -> 240.60487 | F28: =F27-E27 -> 192.0353 | G28: =G27-F27 -> 190.49322 | H28: =H27-G27 -> 186.64268 | I28: =I27-H27 -> 208.34035
C30: Free cash flow to firm
C31: Capital expenditure as % of revenue | D31: =-'Cash Flow'!H45/'P&L'!H7 -> 0.040598377 | E31: =Assumptions!D20 -> 0.04 | F31: =Assumptions!E20 -> 0.04 | G31: =Assumptions!F20 -> 0.039 | H31: =Assumptions!G20 -> 0.038 | I31: =Assumptions!H20 -> 0.038
C32: Capital expenditure | D32: =-'Cash Flow'!H45 -> 592.77 | E32: =E7*E31 -> 645.35669 | F32: =F7*F31 -> 709.89235 | G32: =G7*G31 -> 757.89883 | H32: =H7*H31 -> 804.92742 | I32: =I7*I31 -> 873.34625
C33: NOPAT | D33: =D16 -> 2324.955 | E33: =E16 -> 2592.785 | F33: =F16 -> 2878.4715 | G33: =G16 -> 3180.8431 | H33: =H16 -> 3482.8786 | I33: =I16 -> 3813.1217
C34: D&A | D34: =D12 -> 394.71 | E34: =E12 -> 435.61576 | F34: =F12 -> 479.17734 | G34: =G12 -> 524.69919 | H34: =H12 -> 571.92211 | I34: =I12 -> 620.53549
C35: Change in core operating net working capital | D35: =D28 -> 275.88 | E35: =E28 -> 240.60487 | F35: =F28 -> 192.0353 | G35: =G28 -> 190.49322 | H35: =H28 -> 186.64268 | I35: =I28 -> 208.34035
C36: Forecast FCFF | D36: =FCF!H12 -> 2276.0281 | E36: =E33+E34-E32-E35 -> 2142.4392 | F36: =F33+F34-F32-F35 -> 2455.7212 | G36: =G33+G34-G32-G35 -> 2757.1502 | H36: =H33+H34-H32-H35 -> 3063.2306 | I36: =I33+I34-I32-I35 -> 3351.9705
C37: FCFF margin | D37: =D36/D7 -> 0.15588347 | E37: =E36/E7 -> 0.13279101 | F37: =F36/F7 -> 0.13837147 | G37: =G36/G7 -> 0.14187759 | H37: =H36/H7 -> 0.14461274 | I37: =I36/I7 -> 0.14584694
C39: FY:26 historical FCFF is cash-flow based. Forecast FCFF uses NOPAT + D&A − capex − change in core operating net working capital.

Sheet DCF
C2: Discounted cash flow valuation
C3: Base-case FCFF valuation as at 31 March 2026 | ₹ crore unless stated
C5: Metric | D5: FY:27E | E5: FY:28E | F5: FY:29E | G5: FY:30E | H5: FY:31E | I5: Terminal
C6: Present value of forecast cash flows
C7: Forecast FCFF | D7: =Forecast!E36 -> 2142.4392 | E7: =Forecast!F36 -> 2455.7212 | F7: =Forecast!G36 -> 2757.1502 | G7: =Forecast!H36 -> 3063.2306 | H7: =Forecast!I36 -> 3351.9705 | I7: =H7*(1+Assumptions!$D$49) -> 3519.5691
C8: Discount period | D8: 1 | E8: 2 | F8: 3 | G8: 4 | H8: 5
C9: Discount factor | D9: =1/(1+Assumptions!$D$48)^1 -> 0.89274603 | E9: =1/(1+Assumptions!$D$48)^2 -> 0.79699547 | F9: =1/(1+Assumptions!$D$48)^3 -> 0.71151454 | G9: =1/(1+Assumptions!$D$48)^4 -> 0.63520178 | H9: =1/(1+Assumptions!$D$48)^5 -> 0.56707387 | I9: =H9 -> 0.56707387
C10: Present value of FCFF | D10: =D7*D9 -> 1912.6541 | E10: =E7*E9 -> 1957.1987 | F10: =F7*F9 -> 1961.7525 | G10: =G7*G9 -> 1945.7695 | H10: =H7*H9 -> 1900.8149 | I10: =D15*I9 -> 28455.556
C12: Enterprise-to-equity valuation
C13: Selected WACC | D13: =Assumptions!D48 -> 0.1201394 | E13: Linked to WACC build
C14: Terminal growth | D14: =Assumptions!D49 -> 0.05 | E14: Editable long-term growth
C15: Terminal value | D15: =I7/(D13-D14) -> 50179.629 | E15: FY:31 FCFF grown at g and capitalised
C16: Present value of terminal value | D16: =I10 -> 28455.556 | E16: Terminal value discounted five periods
C17: Present value of explicit forecast | D17: =SUM(D10:H10) -> 9678.1897 | E17: Sum of forecast-period present values
C18: Enterprise value | D18: =D16+D17 -> 38133.746 | E18: Operating-business value
C19: Selected net financial assets | D19: ='Valuation Bridge'!E26 -> 4146.42 | E19: Market-adjusted financial assets less debt and leases
C20: Equity value | D20: =D18+D19 -> 42280.166 | E20: Enterprise value plus selected net financial assets
C21: Diluted shares (crore) | D21: ='Valuation Bridge'!E34 -> 101.99584 | E21: Bonus-adjusted diluted denominator
C22: Implied value per share | D22: =D20/D21 -> 414.52836 | E22: Base-case DCF output
C23: Market-price reference per share | D23: =Assumptions!D42 -> 1566.9 | E23: 11 Sep 2026 market reference
C24: Upside / (downside) to reference | D24: =D22/D23-1 -> -0.73544683 | E24: DCF value relative to market reference
C25: Terminal value as % of enterprise value | D25: =D16/D18 -> 0.74620407 | E25: Sensitivity check; a high share indicates long-duration assumptions
C28: Implied value per share sensitivity
C29: WACC / terminal growth | D29: 0.04 | E29: 0.045 | F29: 0.05 | G29: 0.055 | H29: 0.06 | I29: ₹ per share
C30: 0.1 | D30: =(Forecast!E36/(1+$C30)+Forecast!F36/(1+$C30)^2+Forecast!G36/(1+$C30)^3+Forecast!H36/(1+$C30)^4+Forecast!I36/(1+$C30)^5+Forecast!I36*(1+D$29)/(($C30-D$29)*(1+$C30)^5)+'Valuation Bridge'!$E$26)/'Valuation Bridge'!$E$34 -> 494.57587 | E30: =(Forecast!E36/(1+$C30)+Forecast!F36/(1+$C30)^2+Forecast!G36/(1+$C30)^3+Forecast!H36/(1+$C30)^4+Forecast!I36/(1+$C30)^5+Forecast!I36*(1+E$29)/(($C30-E$29)*(1+$C30)^5)+'Valuation Bridge'!$E$26)/'Valuation Bridge'!$E$34 -> 528.58559 | F30: =(Forecast!E36/(1+$C30)+Forecast!F36/(1+$C30)^2+Forecast!G36/(1+$C30)^3+Forecast!H36/(1+$C30)^4+Forecast!I36/(1+$C30)^5+Forecast!I36*(1+F$29)/(($C30-F$29)*(1+$C30)^5)+'Valuation Bridge'!$E$26)/'Valuation Bridge'!$E$34 -> 569.39726 | G30: =(Forecast!E36/(1+$C30)+Forecast!F36/(1+$C30)^2+Forecast!G36/(1+$C30)^3+Forecast!H36/(1+$C30)^4+Forecast!I36/(1+$C30)^5+Forecast!I36*(1+G$29)/(($C30-G$29)*(1+$C30)^5)+'Valuation Bridge'!$E$26)/'Valuation Bridge'!$E$34 -> 619.27818 | H30: =(Forecast!E36/(1+$C30)+Forecast!F36/(1+$C30)^2+Forecast!G36/(1+$C30)^3+Forecast!H36/(1+$C30)^4+Forecast!I36/(1+$C30)^5+Forecast!I36*(1+H$29)/(($C30-H$29)*(1+$C30)^5)+'Valuation Bridge'!$E$26)/'Valuation Bridge'!$E$34 -> 681.62934
C31: 0.11 | D31: =(Forecast!E36/(1+$C31)+Forecast!F36/(1+$C31)^2+Forecast!G36/(1+$C31)^3+Forecast!H36/(1+$C31)^4+Forecast!I36/(1+$C31)^5+Forecast!I36*(1+D$29)/(($C31-D$29)*(1+$C31)^5)+'Valuation Bridge'!$E$26)/'Valuation Bridge'!$E$34 -> 427.92962 | E31: =(Forecast!E36/(1+$C31)+Forecast!F36/(1+$C31)^2+Forecast!G36/(1+$C31)^3+Forecast!H36/(1+$C31)^4+Forecast!I36/(1+$C31)^5+Forecast!I36*(1+E$29)/(($C31-E$29)*(1+$C31)^5)+'Valuation Bridge'!$E$26)/'Valuation Bridge'!$E$34 -> 451.71908 | F31: =(Forecast!E36/(1+$C31)+Forecast!F36/(1+$C31)^2+Forecast!G36/(1+$C31)^3+Forecast!H36/(1+$C31)^4+Forecast!I36/(1+$C31)^5+Forecast!I36*(1+F$29)/(($C31-F$29)*(1+$C31)^5)+'Valuation Bridge'!$E$26)/'Valuation Bridge'!$E$34 -> 479.47344 | G31: =(Forecast!E36/(1+$C31)+Forecast!F36/(1+$C31)^2+Forecast!G36/(1+$C31)^3+Forecast!H36/(1+$C31)^4+Forecast!I36/(1+$C31)^5+Forecast!I36*(1+G$29)/(($C31-G$29)*(1+$C31)^5)+'Valuation Bridge'!$E$26)/'Valuation Bridge'!$E$34 -> 512.27405 | H31: =(Forecast!E36/(1+$C31)+Forecast!F36/(1+$C31)^2+Forecast!G36/(1+$C31)^3+Forecast!H36/(1+$C31)^4+Forecast!I36/(1+$C31)^5+Forecast!I36*(1+H$29)/(($C31-H$29)*(1+$C31)^5)+'Valuation Bridge'!$E$26)/'Valuation Bridge'!$E$34 -> 551.63478
C32: 0.12 | D32: =(Forecast!E36/(1+$C32)+Forecast!F36/(1+$C32)^2+Forecast!G36/(1+$C32)^3+Forecast!H36/(1+$C32)^4+Forecast!I36/(1+$C32)^5+Forecast!I36*(1+D$29)/(($C32-D$29)*(1+$C32)^5)+'Valuation Bridge'!$E$26)/'Valuation Bridge'!$E$34 -> 377.99774 | E32: =(Forecast!E36/(1+$C32)+Forecast!F36/(1+$C32)^2+Forecast!G36/(1+$C32)^3+Forecast!H36/(1+$C32)^4+Forecast!I36/(1+$C32)^5+Forecast!I36*(1+E$29)/(($C32-E$29)*(1+$C32)^5)+'Valuation Bridge'!$E$26)/'Valuation Bridge'!$E$34 -> 395.40235 | F32: =(Forecast!E36/(1+$C32)+Forecast!F36/(1+$C32)^2+Forecast!G36/(1+$C32)^3+Forecast!H36/(1+$C32)^4+Forecast!I36/(1+$C32)^5+Forecast!I36*(1+F$29)/(($C32-F$29)*(1+$C32)^5)+'Valuation Bridge'!$E$26)/'Valuation Bridge'!$E$34 -> 415.29334 | G32: =(Forecast!E36/(1+$C32)+Forecast!F36/(1+$C32)^2+Forecast!G36/(1+$C32)^3+Forecast!H36/(1+$C32)^4+Forecast!I36/(1+$C32)^5+Forecast!I36*(1+G$29)/(($C32-G$29)*(1+$C32)^5)+'Valuation Bridge'!$E$26)/'Valuation Bridge'!$E$34 -> 438.24448 | H32: =(Forecast!E36/(1+$C32)+Forecast!F36/(1+$C32)^2+Forecast!G36/(1+$C32)^3+Forecast!H36/(1+$C32)^4+Forecast!I36/(1+$C32)^5+Forecast!I36*(1+H$29)/(($C32-H$29)*(1+$C32)^5)+'Valuation Bridge'!$E$26)/'Valuation Bridge'!$E$34 -> 465.02081 | I32: Near base WACC
C33: 0.13 | D33: =(Forecast!E36/(1+$C33)+Forecast!F36/(1+$C33)^2+Forecast!G36/(1+$C33)^3+Forecast!H36/(1+$C33)^4+Forecast!I36/(1+$C33)^5+Forecast!I36*(1+D$29)/(($C33-D$29)*(1+$C33)^5)+'Valuation Bridge'!$E$26)/'Valuation Bridge'!$E$34 -> 339.20668 | E33: =(Forecast!E36/(1+$C33)+Forecast!F36/(1+$C33)^2+Forecast!G36/(1+$C33)^3+Forecast!H36/(1+$C33)^4+Forecast!I36/(1+$C33)^5+Forecast!I36*(1+E$29)/(($C33-E$29)*(1+$C33)^5)+'Valuation Bridge'!$E$26)/'Valuation Bridge'!$E$34 -> 352.38052 | F33: =(Forecast!E36/(1+$C33)+Forecast!F36/(1+$C33)^2+Forecast!G36/(1+$C33)^3+Forecast!H36/(1+$C33)^4+Forecast!I36/(1+$C33)^5+Forecast!I36*(1+F$29)/(($C33-F$29)*(1+$C33)^5)+'Valuation Bridge'!$E$26)/'Valuation Bridge'!$E$34 -> 367.2011 | G33: =(Forecast!E36/(1+$C33)+Forecast!F36/(1+$C33)^2+Forecast!G36/(1+$C33)^3+Forecast!H36/(1+$C33)^4+Forecast!I36/(1+$C33)^5+Forecast!I36*(1+G$29)/(($C33-G$29)*(1+$C33)^5)+'Valuation Bridge'!$E$26)/'Valuation Bridge'!$E$34 -> 383.99775 | H33: =(Forecast!E36/(1+$C33)+Forecast!F36/(1+$C33)^2+Forecast!G36/(1+$C33)^3+Forecast!H36/(1+$C33)^4+Forecast!I36/(1+$C33)^5+Forecast!I36*(1+H$29)/(($C33-H$29)*(1+$C33)^5)+'Valuation Bridge'!$E$26)/'Valuation Bridge'!$E$34 -> 403.19393
C34: 0.14 | D34: =(Forecast!E36/(1+$C34)+Forecast!F36/(1+$C34)^2+Forecast!G36/(1+$C34)^3+Forecast!H36/(1+$C34)^4+Forecast!I36/(1+$C34)^5+Forecast!I36*(1+D$29)/(($C34-D$29)*(1+$C34)^5)+'Valuation Bridge'!$E$26)/'Valuation Bridge'!$E$34 -> 308.21242 | E34: =(Forecast!E36/(1+$C34)+Forecast!F36/(1+$C34)^2+Forecast!G36/(1+$C34)^3+Forecast!H36/(1+$C34)^4+Forecast!I36/(1+$C34)^5+Forecast!I36*(1+E$29)/(($C34-E$29)*(1+$C34)^5)+'Valuation Bridge'!$E$26)/'Valuation Bridge'!$E$34 -> 318.45348 | F34: =(Forecast!E36/(1+$C34)+Forecast!F36/(1+$C34)^2+Forecast!G36/(1+$C34)^3+Forecast!H36/(1+$C34)^4+Forecast!I36/(1+$C34)^5+Forecast!I36*(1+F$29)/(($C34-F$29)*(1+$C34)^5)+'Valuation Bridge'!$E$26)/'Valuation Bridge'!$E$34 -> 329.83243 | G34: =(Forecast!E36/(1+$C34)+Forecast!F36/(1+$C34)^2+Forecast!G36/(1+$C34)^3+Forecast!H36/(1+$C34)^4+Forecast!I36/(1+$C34)^5+Forecast!I36*(1+G$29)/(($C34-G$29)*(1+$C34)^5)+'Valuation Bridge'!$E$26)/'Valuation Bridge'!$E$34 -> 342.55008 | H34: =(Forecast!E36/(1+$C34)+Forecast!F36/(1+$C34)^2+Forecast!G36/(1+$C34)^3+Forecast!H36/(1+$C34)^4+Forecast!I36/(1+$C34)^5+Forecast!I36*(1+H$29)/(($C34-H$29)*(1+$C34)^5)+'Valuation Bridge'!$E$26)/'Valuation Bridge'!$E$34 -> 356.85744
C36: Sensitivity formulas re-discount both the explicit FCFF period and the terminal value at each WACC / growth pair.
C38: Important | D38: The result is highly sensitive to WACC, terminal growth and sustained margins. Use it as a valuation framework, not as a stand-alone investment recommendation.

Sheet Valuation Bridge
C2: Valuation bridge
C3: FY:25 comparator and FY:26 valuation-date bridge | ₹ crore unless stated
C5: Metric | D5: FY:25 | E5: FY:26 | F5: Source | G5: Valuation treatment
C6: Cash, bank balances and investments
C7: Cash and cash equivalents | D7: ='Balance Sheet'!G25 -> 323.94 | E7: ='Balance Sheet'!H25 -> 232.49 | F7: Balance sheet | G7: Add to equity value
C8: Bank balances other than cash equivalents | D8: ='Balance Sheet'!G26 -> 12.27 | E8: ='Balance Sheet'!H26 -> 66.41 | F8: Balance sheet | G8: Add to equity value
C9: Current quoted investments — carrying value | D9: 3149.59 | E9: 3903.02 | F9: Notes 8–9 | G9: Use market value below
C10: Current unquoted investments — carrying value | D10: 12.37 | E10: 16.81 | F10: Notes 8–9 | G10: Carrying value
C11: Total current investments | D11: =SUM(D9:D10) -> 3161.96 | E11: =SUM(E9:E10) -> 3919.83 | F11: Notes 8–9 | G11: Reconciles to balance sheet
C12: Non-current investments — carrying value | D12: ='Balance Sheet'!G14 -> 289.29 | E12: ='Balance Sheet'!H14 -> 263.56 | F12: Note 8 | G12: Carrying value; haircut optional
C13: Gross financial assets — carrying value | D13: =SUM(D7:D8,D11:D12) -> 3787.46 | E13: =SUM(E7:E8,E11:E12) -> 4482.29 | F13: Calculated | G13: Book-value reference
C14: Current quoted investments — market value | D14: 3149.59 | E14: 3984.36 | F14: Note 9 | G14: Market value
C15: Market-value uplift on current quoted investments | D15: =D14-D9 -> 0 | E15: =E14-E9 -> 81.34 | F15: Calculated | G15: Valuation adjustment
C16: Gross financial assets — market adjusted | D16: =D13+D15 -> 3787.46 | E16: =E13+E15 -> 4563.63 | F16: Calculated | G16: Selected gross assets
C18: Borrowings and lease liabilities
C19: Current borrowings | D19: ='Balance Sheet'!G47 -> 147.18 | E19: ='Balance Sheet'!H47 -> 105.91 | F19: Note 23 | G19: Subtract from enterprise value
C20: Non-current lease liabilities | D20: ='Balance Sheet'!G41 -> 220.23 | E20: ='Balance Sheet'!H41 -> 219.45 | F20: Balance sheet / Note 53 | G20: Subtract from enterprise value
C21: Current lease liabilities | D21: ='Balance Sheet'!G48 -> 86.73 | E21: ='Balance Sheet'!H48 -> 91.85 | F21: Balance sheet / Note 53 | G21: Subtract from enterprise value
C22: Total lease liabilities | D22: =SUM(D20:D21) -> 306.96 | E22: =SUM(E20:E21) -> 311.3 | F22: Calculated | G22: Debt-like item
C23: Lease-note closing-balance reconciliation | D23: =ROUND(D22-306.96,2) -> 0 | E23: =ROUND(E22-311.3,2) -> 0 | F23: Note 53 | G23: Check; should be zero
C24: Total borrowings and lease liabilities | D24: =D19+D22 -> 454.14 | E24: =E19+E22 -> 417.21 | F24: Calculated | G24: Total deduction
C25: Net financial assets — carrying value | D25: =D13-D24 -> 3333.32 | E25: =E13-E24 -> 4065.08 | F25: Calculated | G25: Book-value reference
C26: Selected net financial assets — market adjusted | D26: =D16-D24 -> 3333.32 | E26: =E16-E24 -> 4146.42 | F26: Calculated | G26: Selected equity bridge adjustment
C28: Share-count bridge
C29: Closing paid-up shares (crore shares) | D29: 50.864875 | E29: 101.77663 | F29: Note 21 | G29: Year-end basic shares
C30: Equity share capital (₹ crore; face value ₹1) | D30: ='Balance Sheet'!G35 -> 50.86 | E30: ='Balance Sheet'!H35 -> 101.78 | F30: Balance sheet | G30: Rounding check
C31: Share-capital rounding reconciliation | D31: =D29-D30 -> 0.0048755 | E31: =E29-E30 -> -0.0033712 | F31: Calculated | G31: Within ₹0.01 crore
C32: Gross ESOP shares reserved (crore shares) | D32: 0.2623874 | E32: 0.4500448 | F32: Note 21 | G32: Reference only; not all options are incremental
C33: Reported diluted weighted-average shares (derived, crore) | D33: ='P&L'!G32/'P&L'!G35 -> 101.97642 | E33: ='P&L'!H32/'P&L'!H35 -> 101.99584 | F33: P&L | G33: Bonus-adjusted diluted denominator
C34: Selected per-share denominator (crore shares) | D34: =D33 -> 101.97642 | E34: =E33 -> 101.99584 | F34: Selected | G34: Used for future implied value per share
C35: Selected bridge adjustment per diluted share (₹) | D35: =D26/D34 -> 32.687163 | E35: =E26/E34 -> 40.652836 | F35: Calculated | G35: Financial-assets contribution per share
C36: Method note | D36: Current quoted investments use the reported market value. Current unquoted and non-current investments remain at carrying value; apply a haircut only if later research supports it. FY:25 EPS and diluted shares are restated for the FY:26 1:1 bonus issue.

Sheet Revenue
C2: Historical revenue bridge
C3: Revenue-note detail and forecast calibration | ₹ crore
C5: Metric | D5: FY:22 | E5: FY:23 | F5: FY:24 | G5: FY:25 | H5: FY:26
C6: Revenue from operations bridge
C7: Sale of products | D7: 9620.11 | E7: 11469.26 | F7: 12023.98 | G7: 12761.11 | H7: 14234.71
C8: Sale of services | D8: 259.86 | E8: 282.36 | F8: 313.09 | G8: 331.65 | H8: 316.55
C9: Financial-services income | D9: 0 | E9: 0 | F9: 0 | G9: 1.09 | H9: 2.22
C10: Other operating revenue | D10: 40.99 | E10: 47.48 | F10: 45.92 | G10: 46.46 | H10: 47.35
C11: Revenue from operations | D11: =SUM(D7:D10) -> 9920.96 | E11: =SUM(E7:E10) -> 11799.1 | F11: =SUM(F7:F10) -> 12382.99 | G11: =SUM(G7:G10) -> 13140.31 | H11: =SUM(H7:H10) -> 14600.83
C12: P&L revenue from operations | D12: ='P&L'!D7 -> 9920.96 | E12: ='P&L'!E7 -> 11799.1 | F12: ='P&L'!F7 -> 12382.99 | G12: ='P&L'!G7 -> 13140.31 | H12: ='P&L'!H7 -> 14600.83
C13: Revenue-note reconciliation | D13: =ROUND(D11-D12,2) -> 0 | E13: =ROUND(E11-E12,2) -> 0 | F13: =ROUND(F11-F12,2) -> 0 | G13: =ROUND(G11-G12,2) -> 0 | H13: =ROUND(H11-H12,2) -> 0
C15: Other operating revenue
C16: Scrap sales | D16: 17.69 | E16: 21.97 | F16: 22.88 | G16: 22.13 | H16: 23.03
C17: Export incentives | D17: 13.91 | E17: 13.26 | F17: 13.45 | G17: 16.35 | H17: 13.72
C18: GST / excise refund | D18: 2.94 | E18: 6.49 | F18: 2.95 | G18: 2.06 | H18: 3.76
C19: Others | D19: 6.45 | E19: 5.76 | F19: 6.64 | G19: 5.92 | H19: 6.84
C20: Other operating revenue | D20: =SUM(D16:D19) -> 40.99 | E20: =SUM(E16:E19) -> 47.48 | F20: =SUM(F16:F19) -> 45.92 | G20: =SUM(G16:G19) -> 46.46 | H20: =SUM(H16:H19) -> 47.35
C22: Revenue mix and growth
C23: Revenue growth | D23: n.a. | E23: =E11/D11-1 -> 0.18931031 | F23: =F11/E11-1 -> 0.049485978 | G23: =G11/F11-1 -> 0.061158089 | H23: =H11/G11-1 -> 0.11114806
C24: Product-revenue growth | D24: n.a. | E24: =E7/D7-1 -> 0.19221714 | F24: =F7/E7-1 -> 0.048365806 | G24: =G7/F7-1 -> 0.061304992 | H24: =H7/G7-1 -> 0.11547585
C25: Service-revenue growth | D25: n.a. | E25: =E8/D8-1 -> 0.086585084 | F25: =F8/E8-1 -> 0.1088327 | G25: =G8/F8-1 -> 0.059280079 | H25: =H8/G8-1 -> -0.045529926
C26: Products as % of revenue | D26: =D7/D11 -> 0.96967531 | E26: =E7/E11 -> 0.97204533 | F26: =F7/F11 -> 0.97100781 | G26: =G7/G11 -> 0.97114223 | H26: =H7/H11 -> 0.97492471
C27: Services as % of revenue | D27: =D8/D11 -> 0.02619303 | E27: =E8/E11 -> 0.023930639 | F27: =F8/F11 -> 0.025283877 | G27: =G8/G11 -> 0.025239131 | H27: =H8/H11 -> 0.021680274
C28: Other operating revenue as % of revenue | D28: =D10/D11 -> 0.0041316566 | E28: =E10/E11 -> 0.0040240357 | F28: =F10/F11 -> 0.0037083128 | G28: =G10/G11 -> 0.0035356852 | H28: =H10/H11 -> 0.0032429663
C29: Financial-services income as % of revenue | D29: =D9/D11 -> 0 | E29: =E9/E11 -> 0 | F29: =F9/F11 -> 0 | G29: =G9/G11 -> 8.2950859e-05 | H29: =H9/H11 -> 0.00015204615
C31: Product contracted-price bridge (comparable from FY:23)
C32: Contracted price | D32: n.a. | E32: 12766.84 | F32: 13711.34 | G32: 14545.98 | H32: 16096.9
C33: Less: variable-consideration components | D33: n.a. | E33: -1297.58 | F33: -1687.36 | G33: -1784.87 | H33: -1862.19
C34: Revenue recognised from sale of products | D34: n.a. | E34: =E32+E33 -> 11469.26 | F34: =F32+F33 -> 12023.98 | G34: =G32+G33 -> 12761.11 | H34: =H32+H33 -> 14234.71
C35: Variable consideration as % of contracted price | D35: n.a. | E35: =-E33/E32 -> 0.10163674 | F35: =-F33/F32 -> 0.1230631 | G35: =-G33/G32 -> 0.12270538 | H35: =-H33/H32 -> 0.11568625
C36: Bridge check vs sale of products | D36: n.a. | E36: =ROUND(E34-E7,2) -> 0 | F36: =ROUND(F34-F7,2) -> 0 | G36: =ROUND(G34-G7,2) -> 0 | H36: =ROUND(H34-H7,2) -> 0
C38: Historical calibration takeaways
C39: Products contribute about 97% of revenue, so product growth should anchor the forecast.
C40: FY:26 growth was product-led: products grew 11.5%, while services declined 4.6%.
C41: Other operating revenue is below 0.5% of revenue and is not a core valuation driver.
C42: Five-year consolidated segment trends are available in the Segment tab.
C43: FY:22 contracted-price disclosure reconciles total contract revenue rather than product revenue; it is excluded from the comparable product bridge.

Sheet P&L
C2: Consolidated profit and loss
C3: Historical actuals | ₹ crore | Expenses use negative signs
C5: Particulars | D5: FY:22 | E5: FY:23 | F5: FY:24 | G5: FY:25 | H5: FY:26
C6: Income
C7: Revenue from operations | D7: 9920.96 | E7: 11799.1 | F7: 12382.99 | G7: 13140.31 | H7: 14600.83
C8: YoY revenue growth | D8: n.a. | E8: =E7/D7-1 -> 0.18931031 | F8: =F7/E7-1 -> 0.049485978 | G8: =G7/F7-1 -> 0.061158089 | H8: =H7/G7-1 -> 0.11114806
C9: Other income | D9: 36.3 | E9: 49.61 | F9: 139.65 | G9: 247.22 | H9: 266.18
C10: Total income | D10: =D7+D9 -> 9957.26 | E10: =E7+E9 -> 11848.71 | F10: =F7+F9 -> 12522.64 | G10: =G7+G9 -> 13387.53 | H10: =H7+H9 -> 14867.01
C11: Expenses
C12: Cost of materials consumed | D12: -5040.74 | E12: -5958.67 | F12: -5102.56 | G12: -5393.15 | H12: -5620.81
C13: Purchases of stock-in-trade | D13: -648.4 | E13: -862.45 | F13: -765.34 | G13: -741.89 | H13: -898.54
C14: Changes in inventories of finished goods, stock-in-trade and WIP | D14: 244.96 | E14: 61.72 | F14: -126.12 | G14: 138.76 | H14: 30.3
C15: Employee benefits expense | D15: -1112.36 | E15: -1245.63 | F15: -1465.07 | G15: -1741.62 | H15: -1941.22
C16: Finance costs | D16: -42.08 | E16: -47.64 | F16: -51.19 | G16: -50.35 | H16: -54.22
C17: Depreciation, amortisation and impairment | D17: -239.61 | E17: -269.74 | F17: -340.66 | G17: -358.48 | H17: -394.71
C18: Other expenses | D18: -1517.13 | E18: -1809.7 | F18: -2216.63 | G18: -2389.9 | H18: -2651.56
C19: Total expenses | D19: =-SUM(D12:D18) -> 8355.36 | E19: =-SUM(E12:E18) -> 10132.11 | F19: =-SUM(F12:F18) -> 10067.57 | G19: =-SUM(G12:G18) -> 10536.63 | H19: =-SUM(H12:H18) -> 11530.76
C20: Profit before share of associates/JV, exceptional items and tax | D20: =D10+SUM(D12:D18) -> 1601.9 | E20: =E10+SUM(E12:E18) -> 1716.6 | F20: =F10+SUM(F12:F18) -> 2455.07 | G20: =G10+SUM(G12:G18) -> 2850.9 | H20: =H10+SUM(H12:H18) -> 3336.25
C21: Share of profit/(loss) in associates and JV (net of tax) | D21: 11.88 | E21: 6.64 | F21: -4.05 | G21: -3.28 | H21: -2.37
C22: Profit before exceptional items and tax | D22: =D20+D21 -> 1613.78 | E22: =E20+E21 -> 1723.24 | F22: =F20+F21 -> 2451.02 | G22: =G20+G21 -> 2847.62 | H22: =H20+H21 -> 3333.88
C23: Exceptional items | D23: 0 | E23: 0 | F23: -71.67 | G23: -24.92 | H23: -13.71
C24: Profit before tax | D24: =D22+D23 -> 1613.78 | E24: =E22+E23 -> 1723.24 | F24: =F22+F23 -> 2379.35 | G24: =G22+G23 -> 2822.7 | H24: =H22+H23 -> 3320.17
C25: Tax and profit
C26: Current tax | D26: -407.94 | E26: -438.17 | F26: -638.63 | G26: -712.62 | H26: -846.13
C27: Deferred tax (net) | D27: 0.92 | E27: 3.8 | F27: 6.7 | G27: -13.91 | H27: -3.32
C28: Total tax expense | D28: =D26+D27 -> -407.02 | E28: =E26+E27 -> -434.37 | F28: =F26+F27 -> -631.93 | G28: =G26+G27 -> -726.53 | H28: =H26+H27 -> -849.45
C29: Effective tax rate | D29: =-D28/D24 -> 0.2522153 | E29: =-E28/E24 -> 0.25206588 | F29: =-F28/F24 -> 0.26558934 | G29: =-G28/G24 -> 0.25738832 | H29: =-H28/H24 -> 0.25584533
C30: Profit for the year | D30: =D24+D28 -> 1206.76 | E30: =E24+E28 -> 1288.87 | F30: =F24+F28 -> 1747.42 | G30: =G24+G28 -> 2096.17 | H30: =H24+H28 -> 2470.72
C31: YoY profit growth | D31: n.a. | E31: =E30/D30-1 -> 0.068041698 | F31: =F30/E30-1 -> 0.35577677 | G31: =G30/F30-1 -> 0.19957995 | H31: =H30/G30-1 -> 0.17868303
C32: Attributable to owners of the company | D32: 1207.56 | E32: 1273.25 | F32: 1729.38 | G32: 2076.24 | H32: 2448.92
C33: Attributable to non-controlling interests | D33: -0.8 | E33: 15.62 | F33: 18.04 | G33: 19.93 | H33: 21.8
C34: Basic EPS | D34: 23.76 | E34: 25.05 | F34: 34.01 | G34: 20.41 | H34: 24.07
C35: Diluted EPS | D35: 23.75 | E35: 25.03 | F35: 33.98 | G35: 20.36 | H35: 24.01
C36: Operating metrics
C37: Operating EBITDA | D37: =SUM(D7,D12:D15,D18) -> 1847.29 | E37: =SUM(E7,E12:E15,E18) -> 1984.37 | F37: =SUM(F7,F12:F15,F18) -> 2707.27 | G37: =SUM(G7,G12:G15,G18) -> 3012.51 | H37: =SUM(H7,H12:H15,H18) -> 3519
C38: EBITDA margin | D38: =D37/D7 -> 0.18620073 | E38: =E37/E7 -> 0.16817978 | F38: =F37/F7 -> 0.21862813 | G38: =G37/G7 -> 0.22925715 | H38: =H37/H7 -> 0.2410137
C39: Operating EBIT | D39: =D37+D17 -> 1607.68 | E39: =E37+E17 -> 1714.63 | F39: =F37+F17 -> 2366.61 | G39: =G37+G17 -> 2654.03 | H39: =H37+H17 -> 3124.29
C40: EBIT margin | D40: =D39/D7 -> 0.16204883 | E40: =E39/E7 -> 0.14531871 | F40: =F39/F7 -> 0.19111782 | G40: =G39/G7 -> 0.20197621 | H40: =H39/H7 -> 0.2139803
C42: EPS comparability: FY:25–FY:26 reflect the FY:26 bonus-share restatement; FY:22–FY:24 are shown as originally reported.

Sheet Segment
C2: Consolidated segment analysis
C3: Five-year consolidated segment economics plus FY:26 management category indicators | ₹ crore
C5: Metric | D5: FY:22 | E5: FY:23 | F5: FY:24 | G5: FY:25 | H5: FY:26
C6: Consolidated segment net revenue
C7: Consumer & Bazaar | D7: 7770.44 | E7: 9359.81 | F7: 9913.02 | G7: 10335.14 | H7: 11504.5
C8: Business to Business | D8: 2086.82 | E8: 2337.1 | F8: 2408.92 | G8: 2748.35 | H8: 3035.78
C9: Others | D9: 63.7 | E9: 102.19 | F9: 61.06 | G9: 56.82 | H9: 60.55
C10: Total segment net revenue | D10: =SUM(D7:D9) -> 9920.96 | E10: =SUM(E7:E9) -> 11799.1 | F10: =SUM(F7:F9) -> 12383 | G10: =SUM(G7:G9) -> 13140.31 | H10: =SUM(H7:H9) -> 14600.83
C11: P&L revenue from operations | D11: ='P&L'!D7 -> 9920.96 | E11: ='P&L'!E7 -> 11799.1 | F11: ='P&L'!F7 -> 12382.99 | G11: ='P&L'!G7 -> 13140.31 | H11: ='P&L'!H7 -> 14600.83
C12: Segment revenue reconciliation | D12: =ROUND(D10-D11,2) -> 0 | E12: =ROUND(E10-E11,2) -> 0 | F12: =ROUND(F10-F11,2) -> 0.01 | G12: =ROUND(G10-G11,2) -> 0 | H12: =ROUND(H10-H11,2) -> 0
C13: Consumer & Bazaar growth | D13: n.a. | E13: =E7/D7-1 -> 0.20454054 | F13: =F7/E7-1 -> 0.059104832 | G13: =G7/F7-1 -> 0.042582382 | H13: =H7/G7-1 -> 0.11314409
C14: Business to Business growth | D14: n.a. | E14: =E8/D8-1 -> 0.11993368 | F14: =F8/E8-1 -> 0.030730392 | G14: =G8/F8-1 -> 0.14090547 | H14: =H8/G8-1 -> 0.10458275
C15: Total revenue growth | D15: n.a. | E15: =E10/D10-1 -> 0.18931031 | F15: =F10/E10-1 -> 0.049486825 | G15: =G10/F10-1 -> 0.061157232 | H15: =H10/G10-1 -> 0.11114806
C16: Consumer & Bazaar revenue mix | D16: =D7/D10 -> 0.78323469 | E16: =E7/E10 -> 0.79326474 | F16: =F7/F10 -> 0.8005346 | G16: =G7/G10 -> 0.78652178 | H16: =H7/H10 -> 0.78793466
C17: Business to Business revenue mix | D17: =D8/D10 -> 0.21034456 | E17: =E8/E10 -> 0.19807443 | F17: =F8/F10 -> 0.19453444 | G17: =G8/G10 -> 0.20915412 | H17: =H8/H10 -> 0.20791832
C18: Others revenue mix | D18: =D9/D10 -> 0.0064207496 | E18: =E9/E10 -> 0.0086608301 | F18: =F9/F10 -> 0.0049309537 | G18: =G9/G10 -> 0.0043240989 | H18: =H9/H10 -> 0.0041470245
C20: Segment profitability
C21: Consumer & Bazaar segment result | D21: 1933.7 | E21: 2054.82 | F21: 2716.6 | G21: 2979.18 | H21: 3546.3
C22: Business to Business segment result | D22: 152.7 | E22: 234.21 | F22: 319.26 | G22: 489.21 | H22: 529.31
C23: Others segment result | D23: -2.16 | E23: 5.67 | F23: 3.31 | G23: 0.88 | H23: -9.28
C24: Total segment result | D24: 2084.24 | E24: 2294.7 | F24: 3039.17 | G24: 3469.27 | H24: 4066.33
C25: Consumer & Bazaar result margin | D25: =D21/D7 -> 0.24885335 | E25: =E21/E7 -> 0.21953651 | F25: =F21/F7 -> 0.27404363 | G25: =G21/G7 -> 0.28825734 | H25: =H21/H7 -> 0.30825329
C26: Business to Business result margin | D26: =D22/D8 -> 0.073173537 | E26: =E22/E8 -> 0.10021394 | F26: =F22/F8 -> 0.13253242 | G26: =G22/G8 -> 0.17800135 | H26: =H22/H8 -> 0.17435717
C27: Total segment result margin | D27: =D24/D10 -> 0.21008451 | E27: =E24/E10 -> 0.19448093 | F27: =F24/F10 -> 0.24543083 | G27: =G24/G10 -> 0.26401736 | H27: =H24/H10 -> 0.27849992
C28: Operating income | D28: 1638.18 | E28: 1755.4 | F28: 2493.83 | G28: 2885.8 | H28: 3354.3
C29: Operating income margin | D29: =D28/D10 -> 0.16512313 | E29: =E28/E10 -> 0.14877406 | F29: =F28/F10 -> 0.20139142 | G29: =G28/G10 -> 0.2196143 | H29: =H28/H10 -> 0.22973352
C30: Profit before tax | D30: 1613.78 | E30: 1723.24 | F30: 2379.35 | G30: 2822.7 | H30: 3320.17
C31: P&L profit before tax | D31: ='P&L'!D24 -> 1613.78 | E31: ='P&L'!E24 -> 1723.24 | F31: ='P&L'!F24 -> 2379.35 | G31: ='P&L'!G24 -> 2822.7 | H31: ='P&L'!H24 -> 3320.17
C32: Segment-note PBT reconciliation | D32: =ROUND(D30-D31,2) -> 0 | E32: =ROUND(E30-E31,2) -> 0 | F32: =ROUND(F30-F31,2) -> 0 | G32: =ROUND(G30-G31,2) -> 0 | H32: =ROUND(H30-H31,2) -> 0
C34: Revenue by geography
C35: India | D35: 8458.5 | E35: 10243.58 | F35: 10937.98 | G35: 11690.2 | H35: 13133.99
C36: Outside India | D36: 1462.46 | E36: 1555.52 | F36: 1445.01 | G36: 1450.11 | H36: 1466.84
C37: Total geographic revenue | D37: =SUM(D35:D36) -> 9920.96 | E37: =SUM(E35:E36) -> 11799.1 | F37: =SUM(F35:F36) -> 12382.99 | G37: =SUM(G35:G36) -> 13140.31 | H37: =SUM(H35:H36) -> 14600.83
C38: India revenue growth | D38: n.a. | E38: =E35/D35-1 -> 0.21103978 | F38: =F35/E35-1 -> 0.0677888 | G38: =G35/F35-1 -> 0.068771382 | H38: =H35/G35-1 -> 0.1235043
C39: Outside-India revenue growth | D39: n.a. | E39: =E36/D36-1 -> 0.06363251 | F39: =F36/E36-1 -> -0.071043767 | G39: =G36/F36-1 -> 0.0035293873 | H39: =H36/G36-1 -> 0.011537056
C40: Outside India revenue share | D40: =D36/D37 -> 0.14741114 | E40: =E36/E37 -> 0.13183378 | F40: =F36/F37 -> 0.11669314 | G40: =G36/G37 -> 0.11035584 | H40: =H36/H37 -> 0.10046278
C42: Capital intensity and statement checks
C43: Consumer & Bazaar segment assets | D43: 6804 | E43: 7319.6 | F43: 7281.43 | G43: 7745.69 | H43: 8341.12
C44: Business to Business segment assets | D44: 1850.86 | E44: 1830.36 | F44: 1862.11 | G44: 2122.56 | H44: 2306.67
C45: Others segment assets | D45: 11.74 | E45: 17.07 | F45: 9.25 | G45: 32.62 | H45: 46.55
...

Sheet Balance Sheet
C2: Consolidated balance sheet
C3: Historical actuals | ₹ crore
C5: Particulars | D5: FY:22 | E5: FY:23 | F5: FY:24 | G5: FY:25 | H5: FY:26
C6: Assets
C7: Non-current assets
C8: Property, plant and equipment | D8: 1554.86 | E8: 1690.88 | F8: 2206.49 | G8: 2409.82 | H8: 2515.3
C9: Right-of-use assets | D9: 202.93 | E9: 309.9 | F9: 347.97 | G9: 426.31 | H9: 415.42
C10: Capital work-in-progress | D10: 225.42 | E10: 405.94 | F10: 148.09 | G10: 128.95 | H10: 328.87
C11: Goodwill | D11: 1286.83 | E11: 1289.76 | F11: 1281.72 | G11: 1282.21 | H11: 1287.04
C12: Other intangible assets | D12: 1658.64 | E12: 1623.54 | F12: 1614.45 | G12: 1586.95 | H12: 1555.87
C13: Investments accounted for using equity method | D13: 60.66 | E13: 95.02 | F13: 104.97 | G13: 100.07 | H13: 166.22
C14: Non-current investments | D14: 224.43 | E14: 254.63 | F14: 259.91 | G14: 289.29 | H14: 263.56
C15: Non-current loans | D15: 5.05 | E15: 6.2 | F15: 7.75 | G15: 6.33 | H15: 6.78
C16: Other non-current financial assets | D16: 64.45 | E16: 68.08 | F16: 71.65 | G16: 69.97 | H16: 52.02
C17: Deferred tax assets (net) | D17: 21.28 | E17: 20.15 | F17: 28.34 | G17: 27.78 | H17: 34.03
C18: Income tax assets (net) | D18: 140.08 | E18: 148.44 | F18: 147.76 | G18: 173.06 | H18: 193.13
C19: Other non-current assets | D19: 55.38 | E19: 50.96 | F19: 48.44 | G19: 48.74 | H19: 82.77
C20: Total non-current assets | D20: =SUM(D8:D19) -> 5500.01 | E20: =SUM(E8:E19) -> 5963.5 | F20: =SUM(F8:F19) -> 6267.54 | G20: =SUM(G8:G19) -> 6549.48 | H20: =SUM(H8:H19) -> 6901.01
C21: Current assets
C22: Inventories | D22: 1695.09 | E22: 1817.08 | F22: 1414.9 | G22: 1685.09 | H22: 1737.6
C23: Current investments | D23: 173.52 | E23: 531.2 | F23: 1870.16 | G23: 3161.96 | H23: 3919.83
C24: Trade receivables | D24: 1430.54 | E24: 1535.27 | F24: 1674.69 | G24: 1811.15 | H24: 2181.1
C25: Cash and cash equivalents | D25: 352.07 | E25: 310.16 | F25: 515.14 | G25: 323.94 | H25: 232.49
C26: Bank balances other than cash and cash equivalents | D26: 3.1 | E26: 16.49 | F26: 18.15 | G26: 12.27 | H26: 66.41
C27: Current loans | D27: 17.22 | E27: 27.32 | F27: 34.16 | G27: 37.76 | H27: 37.36
C28: Other current financial assets | D28: 86.01 | E28: 86.08 | F28: 26.1 | G28: 35.84 | H28: 39.05
C29: Other current assets, current tax assets and assets held for sale | D29: 258.06 | E29: 237.92 | F29: 283.11 | G29: 393.98 | H29: 318.04
C30: Total current assets | D30: =SUM(D22:D29) -> 4015.61 | E30: =SUM(E22:E29) -> 4561.52 | F30: =SUM(F22:F29) -> 5836.41 | G30: =SUM(G22:G29) -> 7461.99 | H30: =SUM(H22:H29) -> 8531.88
C31: Total assets | D31: =D20+D30 -> 9515.62 | E31: =E20+E30 -> 10525.02 | F31: =F20+F30 -> 12103.95 | G31: =G20+G30 -> 14011.47 | H31: =H20+H30 -> 15432.89
C33: Equity and liabilities
C34: Equity
C35: Equity share capital | D35: 50.83 | E35: 50.83 | F35: 50.86 | G35: 50.86 | H35: 101.78
C36: Other equity | D36: 6352.88 | E36: 7161.45 | F36: 8356.3 | G36: 9703.6 | H36: 10730.39
C37: Equity attributable to owners | D37: =D35+D36 -> 6403.71 | E37: =E35+E36 -> 7212.28 | F37: =F35+F36 -> 8407.16 | G37: =G35+G36 -> 9754.46 | H37: =H35+H36 -> 10832.17
C38: Non-controlling interests | D38: 198.9 | E38: 233.64 | F38: 209.85 | G38: 203.3 | H38: 216.48
C39: Total equity | D39: =D37+D38 -> 6602.61 | E39: =E37+E38 -> 7445.92 | F39: =F37+F38 -> 8617.01 | G39: =G37+G38 -> 9957.76 | H39: =H37+H38 -> 11048.65
C40: Non-current liabilities
C41: Non-current borrowings and lease liabilities | D41: 97.76 | E41: 175.63 | F41: 193.83 | G41: 220.23 | H41: 219.45
C42: Other financial liabilities | D42: 19.94 | E42: 14.45 | F42: 4.42 | G42: 3.87 | H42: 10.27
C43: Provisions | D43: 71.83 | E43: 80.25 | F43: 98.73 | G43: 134.36 | H43: 156.5
...

Sheet Cash Flow
C2: Consolidated cash flow
C3: Historical actuals | ₹ crore | Cash inflows positive, outflows negative
C5: Particulars | D5: FY:22 | E5: FY:23 | F5: FY:24 | G5: FY:25 | H5: FY:26
C6: Cash flow from operating activities
C7: Profit before tax | D7: 1613.78 | E7: 1723.24 | F7: 2379.35 | G7: 2822.7 | H7: 3320.17
C8: Adjustments
C9: Share of loss/(profit) in associates and JV (net of tax) | D9: -11.88 | E9: -6.64 | F9: 4.05 | G9: 3.28 | H9: 2.37
C10: Finance costs | D10: 42.08 | E10: 47.64 | F10: 51.19 | G10: 50.35 | H10: 54.22
C11: Interest income | D11: -4.58 | E11: -7.63 | F11: -12.1 | G11: -15.45 | H11: -18.11
C12: Dividend income | D12: -1.22 | E12: -1.21 | F12: -0.33 | G12: 0 | H12: 0
C13: Dividend from associate | D13: 2.8 | E13: 7.45 | F13: 0 | G13: 0 | H13: 0
C14: Loss/(profit) on disposal of PPE (net) | D14: 9.12 | E14: -0.55 | F14: 5.23 | G14: 1.35 | H14: 4.67
C15: Net gain on financial assets designated at FVTPL | D15: -11.93 | E15: -18.89 | F15: -91.2 | G15: -219.85 | H15: -233.14
C16: Allowance for doubtful debts and advances (net) | D16: 16.73 | E16: 6.91 | F16: 2.95 | G16: 21.42 | H16: 20.56
C17: Liabilities no longer required written back | D17: 0 | E17: 0 | F17: 0 | G17: 0 | H17: -5.12
C18: Provision for write-down of inventories | D18: 0 | E18: 0 | F18: 0 | G18: 8.28 | H18: 24.79
C19: Depreciation, amortisation and impairment | D19: 239.61 | E19: 269.74 | F19: 340.66 | G19: 358.48 | H19: 394.71
C20: Unrealised foreign-exchange loss/(gain) | D20: -13.56 | E20: 10.92 | F20: -58.06 | G20: -0.3 | H20: 1.99
... C25: Equity-settled share-based payments | D25: 28.09 | E25: 14.13 | F25: 9.07 | G25: 88.91 | H25: 130.69
C26: Operating cash flow before working-capital changes | D26: =SUM(D7,D9:D25) -> 1927.74 | E26: =SUM(E7,E9:E25) -> 2047.75 | F26: =SUM(F7,F9:F25) -> 2797.85 | G26: =SUM(G7,G9:G25) -> 3220.13 | H26: =SUM(H7,H9:H25) -> 3741.54
C27: Working capital changes
C28: Trade receivables | D28: -122.71 | E28: -83.75 | F28: -143.89 | G28: -156.33 | H28: -367.54
C29: Inventories | D29: -460.18 | E29: -143.15 | F29: 388.75 | G29: -277.91 | H29: -60.61
C30: Non-current loans | D30: -0.2 | E30: -1.15 | F30: -1.43 | G30: -0.24 | H30: -0.45
C31: Current loans | D31: -0.33 | E31: -10.1 | F31: -8 | G31: -8.82 | H31: 0.4
C32: Other non-current financial assets | D32: -10.63 | E32: -12.93 | F32: -10.74 | G32: 7.81 | H32: 16.34
C33: Other current financial assets | D33: -0.75 | E33: -0.07 | F33: 6.48 | G33: -9.74 | H33: -3.21
C34: Other non-current non-financial assets | D34: 6.89 | E34: -21.71 | F34: -0.9 | G34: -6.4 | H34: -25.87
C35: Other current non-financial assets | D35: -28.11 | E35: 17.95 | F35: -33.07 | G35: -114.35 | H35: 76.56
C36: Trade payables | D36: 75.96 | E36: 31.57 | F36: 103.01 | G36: 238.94 | H36: 130.63
C37: Other current financial liabilities | D37: 17.19 | E37: 156.01 | F37: 260.68 | G37: 149.46 | H37: 187.85
C38: Other non-current financial liabilities | D38: 6.31 | E38: -5.49 | F38: 0 | G38: 0 | H38: 0
C39: Other current non-financial liabilities | D39: 6.19 | E39: -5.73 | F39: 13.37 | G39: -23.2 | H39: -5.06
C40: Cash generated from operations | D40: =D26+SUM(D28:D39) -> 1417.37 | E40: =E26+SUM(E28:E39) -> 1969.2 | F40: =F26+SUM(F28:F39) -> 3372.11 | G40: =G26+SUM(G28:G39) -> 3019.35 | H40: =H26+SUM(H28:H39) -> 3690.58
C41: Income tax paid (net of refunds and interest on refund) | D41: -462 | E41: -411.63 | F41: -648.09 | G41: -732.72 | H41: -862.13
C42: Net cash flow from operating activities | D42: =D40+D41 -> 955.37 | E42: =E40+E41 -> 1557.57 | F42: =F40+F41 -> 2724.02 | G42: =G40+G41 -> 2286.63 | H42: =H40+H41 -> 2828.45
C44: Cash flow from investing activities
C45: Capital expenditure: PPE, ROU assets, intangibles and CWIP | D45: -374.74 | E45: -505.35 | F45: -558.71 | G45: -452.34 | H45: -592.77
C46: Proceeds from disposal of PPE and other intangible assets | D46: 0.77 | E46: 7.63 | F46: 5.76 | G46: 4.27 | H46: 3.59
C47: Cash (outflow)/inflow on investments in associates and JV | D47: 0 | E47: 0 | F47: 19.88 | G47: -13 | H47: -45.19
...

Sheet FCF
C2: Historical FCFF and calibration
C3: Cash-flow-based FCFF plus working-capital and capital-structure diagnostics
C5: Metric | D5: FY:22 | E5: FY:23 | F5: FY:24 | G5: FY:25 | H5: FY:26
C6: Cash-flow-based FCFF
C7: Net cash flow from operating activities | D7: ='Cash Flow'!D42 -> 955.37 | E7: ='Cash Flow'!E42 -> 1557.57 | F7: ='Cash Flow'!F42 -> 2724.02 | G7: ='Cash Flow'!G42 -> 2286.63 | H7: ='Cash Flow'!H42 -> 2828.45
C8: Finance costs | D8: =-'P&L'!D16 -> 42.08 | E8: =-'P&L'!E16 -> 47.64 | F8: =-'P&L'!F16 -> 51.19 | G8: =-'P&L'!G16 -> 50.35 | H8: =-'P&L'!H16 -> 54.22
C9: Effective tax rate | D9: ='P&L'!D29 -> 0.2522153 | E9: ='P&L'!E29 -> 0.25206588 | F9: ='P&L'!F29 -> 0.26558934 | G9: ='P&L'!G29 -> 0.25738832 | H9: ='P&L'!H29 -> 0.25584533
C10: After-tax finance costs | D10: =D8*(1-D9) -> 31.46678 | E10: =E8*(1-E9) -> 35.631582 | F10: =F8*(1-F9) -> 37.594482 | G10: =G8*(1-G9) -> 37.390498 | H10: =H8*(1-H9) -> 40.348066
C11: Capital expenditure | D11: ='Cash Flow'!D45 -> -374.74 | E11: ='Cash Flow'!E45 -> -505.35 | F11: ='Cash Flow'!F45 -> -558.71 | G11: ='Cash Flow'!G45 -> -452.34 | H11: ='Cash Flow'!H45 -> -592.77
C12: Historical FCFF | D12: =D7+D10+D11 -> 612.09678 | E12: =E7+E10+E11 -> 1087.8516 | F12: =F7+F10+F11 -> 2202.9045 | G12: =G7+G10+G11 -> 1871.6805 | H12: =H7+H10+H11 -> 2276.0281
C13: FCFF margin | D13: =D12/'P&L'!D7 -> 0.061697334 | E13: =E12/'P&L'!E7 -> 0.092197844 | F13: =F12/'P&L'!F7 -> 0.17789762 | G13: =G12/'P&L'!G7 -> 0.14243808 | H13: =H12/'P&L'!H7 -> 0.15588347
C15: Core operating working capital
C16: Inventories | D16: ='Balance Sheet'!D22 -> 1695.09 | E16: ='Balance Sheet'!E22 -> 1817.08 | F16: ='Balance Sheet'!F22 -> 1414.9 | G16: ='Balance Sheet'!G22 -> 1685.09 | H16: ='Balance Sheet'!H22 -> 1737.6
C17: Trade receivables | D17: ='Balance Sheet'!D24 -> 1430.54 | E17: ='Balance Sheet'!E24 -> 1535.27 | F17: ='Balance Sheet'!F24 -> 1674.69 | G17: ='Balance Sheet'!G24 -> 1811.15 | H17: ='Balance Sheet'!H24 -> 2181.1
C18: Trade payables | D18: ='Balance Sheet'!D60 -> 1049.29 | E18: ='Balance Sheet'!E60 -> 1063.59 | F18: ='Balance Sheet'!F60 -> 1147.6 | G18: ='Balance Sheet'!G60 -> 1390.05 | H18: ='Balance Sheet'!H60 -> 1536.63
C19: Core operating net working capital | D19: =D16+D17-D18 -> 2076.34 | E19: =E16+E17-E18 -> 2288.76 | F19: =F16+F17-F18 -> 1941.99 | G19: =G16+G17-G18 -> 2106.19 | H19: =H16+H17-H18 -> 2382.07
C20: Change in core operating net working capital | D20: n.a. | E20: =E19-D19 -> 212.42 | F20: =F19-E19 -> -346.77 | G20: =G19-F19 -> 164.2 | H20: =H19-G19 -> 275.88
C21: Revenue from operations | D21: ='P&L'!D7 -> 9920.96 | E21: ='P&L'!E7 -> 11799.1 | F21: ='P&L'!F7 -> 12382.99 | G21: ='P&L'!G7 -> 13140.31 | H21: ='P&L'!H7 -> 14600.83
C22: Direct cost base | D22: =-SUM('P&L'!D12:'P&L'!D14) -> 5444.18 | E22: =-SUM('P&L'!E12:'P&L'!E14) -> 6759.4 | F22: =-SUM('P&L'!F12:'P&L'!F14) -> 5994.02 | G22: =-SUM('P&L'!G12:'P&L'!G14) -> 5996.28 | H22: =-SUM('P&L'!H12:'P&L'!H14) -> 6489.05
C23: Days sales outstanding | D23: =D17/D21*365 -> 52.630703 | E23: =E17/E21*365 -> 47.492906 | F23: =F17/F21*365 -> 49.363025 | G23: =G17/G21*365 -> 50.308535 | H23: =H17/H21*365 -> 54.5244
C24: Days inventory outstanding | D24: =D16/D22*365 -> 113.64574 | E24: =E16/E22*365 -> 98.120277 | F24: =F16/F22*365 -> 86.158955 | G24: =G16/G22*365 -> 102.57324 | H24: =H16/H22*365 -> 97.737573
C25: Days payable outstanding | D25: =D18/D22*365 -> 70.348675 | E25: =E18/E22*365 -> 57.432664 | F25: =F18/F22*365 -> 69.881982 | G25: =G18/G22*365 -> 84.613836 | H25: =H18/H22*365 -> 86.433291
C27: Capital structure bridge
C28: Cash, bank balances and investments — carrying value | D28: ='Balance Sheet'!D62 -> 753.12 | E28: ='Balance Sheet'!E62 -> 1112.48 | F28: ='Balance Sheet'!F62 -> 2663.36 | G28: ='Balance Sheet'!G62 -> 3787.46 | H28: ='Balance Sheet'!H62 -> 4482.29
C29: Borrowings and lease liabilities | D29: ='Balance Sheet'!D61 -> 415.83 | E29: ='Balance Sheet'!E61 -> 390.61 | F29: ='Balance Sheet'!F61 -> 382.47 | G29: ='Balance Sheet'!G61 -> 454.14 | H29: ='Balance Sheet'!H61 -> 417.21
C30: Net cash and investments — carrying value | D30: ='Balance Sheet'!D63 -> 337.29 | E30: ='Balance Sheet'!E63 -> 721.87 | F30: ='Balance Sheet'!F63 -> 2280.89 | G30: ='Balance Sheet'!G63 -> 3333.32 | H30: ='Balance Sheet'!H63 -> 4065.08
C31: The carrying-value bridge is historical. The Valuation Bridge tab uses FY:26 market values for quoted current investments and provides the selected equity-value adjustment.

Sheet Sources & Checks
C2: Sources and checks
C3: Source references, statement reconciliations and overlap checks
C6: Source log
C7: ID | D7: Statement | E7: Periods | F7: Reference | G7: File | H7: Status | I7: Notes
C8: S1 | D8: Consolidated statement of profit and loss | E8: FY:25–FY:26 | F8: Pidilite Industries annual report 2025–26, page 251 | G8: abc725d1-52e9-4c36-9b6d-b534a1ac8a00.png | H8: Entered | I8: User-supplied screenshot
C9: S2 | D9: Consolidated balance sheet | E9: FY:25–FY:26 | F9: Pidilite Industries annual report 2025–26 | G9: e127ac53-53ad-41d1-a758-02364f880468.png | H9: Entered | I9: User-supplied screenshot
C10: S3 | D10: Consolidated cash flow: operating and investing | E10: FY:25–FY:26 | F10: Pidilite Industries annual report 2025–26 | G10: bbcebe16-9eb4-40a5-9b26-d43ac9fd9a36.png | H10: Entered | I10: User-supplied screenshot
C11: S4 | D11: Consolidated cash flow: financing and reconciliation | E11: FY:25–FY:26 | F11: Pidilite Industries annual report 2025–26 | G11: 3de238e5-7fee-4178-85c9-c8e21242801d.png | H11: Entered | I11: User-supplied screenshot
C12: S5 | D12: Consolidated balance sheet | E12: FY:24–FY:25 | F12: Pidilite Industries annual report 2024–25 | G12: a06bb4e6-8506-4a5d-a23b-17afb15f656e.png | H12: Checked | I12: Overlap source
C13: S6 | D13: Consolidated statement of profit and loss | E13: FY:24–FY:25 | F13: Pidilite Industries annual report 2024–25 | G13: 6810b68c-71ab-416d-ad83-df9e58172df9.png | H13: Checked | I13: Overlap source
C14: S7 | D14: Consolidated cash flow: operating and investing | E14: FY:24–FY:25 | F14: Pidilite Industries annual report 2024–25 | G14: aaf89ad5-30d3-4651-b4ef-e0558a973fa3.png | H14: Checked | I14: Overlap source
C15: S8 | D15: Consolidated cash flow: financing and reconciliation | E15: FY:24–FY:25 | F15: Pidilite Industries annual report 2024–25 | G15: d2a03d00-1c1d-47f0-be3d-06744a60d505.png | H15: Checked | I15: Overlap source
C16: S9 | D16: Consolidated balance sheet | E16: FY:23–FY:24 | F16: Pidilite Industries annual report 2023–24 | G16: f17c3b08-0e3f-4c1d-a3fd-78ceb583b7ae.png | H16: Entered | I16: User-supplied screenshot
C17: S10 | D17: Consolidated statement of profit and loss | E17: FY:23–FY:24 | F17: Pidilite Industries annual report 2023–24 | G17: 527df1f1-d2e5-4662-96d5-124ffaccf4c7.png | H17: Entered | I17: User-supplied screenshot
C18: S11 | D18: Consolidated cash flow: operating and investing | E18: FY:23–FY:24 | F18: Pidilite Industries annual report 2023–24 | G18: 69825253-4559-49d7-816a-89513d4dd245.png | H18: Entered | I18: User-supplied screenshot
... C41: S34 | D41: Equity share capital and bonus issue | E41: FY:25–FY:26 | F41: Pidilite Industries annual report 2025–26, consolidated Note 21 | G41: db894c2c-b291-4437-9d33-4639af3e1623.png | H41: Entered | I41: Closing shares, 1:1 bonus issue and ESOP reserve
C43: Statement reconciliations
C44: Check | D44: FY:22 difference | E44: FY:23 difference | F44: FY:24 difference | G44: FY:25 difference | H44: FY:26 difference | I44: Tolerance | J44: Status | K44: Notes
C45: P&L total income vs reported | D45: =ROUND('P&L'!D10-9957.26,2) -> 0 | E45: =ROUND('P&L'!E10-11848.71,2) -> 0 | F45: =ROUND('P&L'!F10-12522.64,2) -> 0 | G45: =ROUND('P&L'!G10-13387.53,2) -> 0 | H45: =ROUND('P&L'!H10-14867.01,2) -> 0 | I45: 0.02 | J45: =IF(AND(ABS(D45)<=I45,ABS(E45)<=I45,ABS(F45)<=I45,ABS(G45)<=I45,ABS(H45)<=I45),"OK","Review") -> OK
C46: P&L total expenses vs reported | D46: =ROUND('P&L'!D19-8355.36,2) -> 0 | E46: =ROUND('P&L'!E19-10132.12,2) -> -0.01 | F46: =ROUND('P&L'!F19-10067.57,2) -> 0 | G46: =ROUND('P&L'!G19-10536.63,2) -> 0 | H46: =ROUND('P&L'!H19-11530.76,2) -> 0 | I46: 0.02 | J46: =IF(AND(ABS(D46)<=I46,ABS(E46)<=I46,ABS(F46)<=I46,ABS(G46)<=I46,ABS(H46)<=I46),"OK","Review") -> OK | K46: FY:23 line-item rounding creates a ₹0.01 crore difference
C47: P&L profit for year vs reported | D47: =ROUND('P&L'!D30-1206.76,2) -> 0 | E47: =ROUND('P&L'!E30-1288.87,2) -> 0 | F47: =ROUND('P&L'!F30-1747.42,2) -> 0 | G47: =ROUND('P&L'!G30-2096.17,2) -> 0 | H47: =ROUND('P&L'!H30-2470.72,2) -> 0 | I47: 0.02 | J47: =IF(AND(ABS(D47)<=I47,ABS(E47)<=I47,ABS(F47)<=I47,ABS(G47)<=I47,ABS(H47)<=I47),"OK","Review") -> OK
C48: Balance-sheet total assets vs reported | D48: =ROUND('Balance Sheet'!D31-9515.62,2) -> 0 | E48: =ROUND('Balance Sheet'!E31-10525.02,2) -> 0 | F48: =ROUND('Balance Sheet'!F31-12103.95,2) -> 0 | G48: =ROUND('Balance Sheet'!G31-14011.47,2) -> 0 | H48: =ROUND('Balance Sheet'!H31-15432.89,2) -> 0 | I48: 0.02 | J48: =IF(AND(ABS(D48)<=I48,ABS(E48)<=I48,ABS(F48)<=I48,ABS(G48)<=I48,ABS(H48)<=I48),"OK","Review") -> OK
C49: Balance-sheet equation | D49: =ROUND('Balance Sheet'!D31-'Balance Sheet'!D57,2) -> 0 | E49: =ROUND('Balance Sheet'!E31-'Balance Sheet'!E57,2) -> 0 | F49: =ROUND('Balance Sheet'!F31-'Balance Sheet'!F57,2) -> 0 | G49: =ROUND('Balance Sheet'!G31-'Balance Sheet'!G57,2) -> 0 | H49: =ROUND('Balance Sheet'!H31-'Balance Sheet'!H57,2) -> 0 | I49: 0.02 | J49: =IF(AND(ABS(D49)<=I49,ABS(E49)<=I49,ABS(F49)<=I49,ABS(G49)<=I49,ABS(H49)<=I49),"OK","Review") -> OK | K49: Assets less equity and liabilities
C50: Operating cash flow vs reported | D50: =ROUND('Cash Flow'!D42-955.37,2) -> 0 | E50: =ROUND('Cash Flow'!E42-1557.57,2) -> 0 | F50: =ROUND('Cash Flow'!F42-2724.03,2) -> -0.01 | G50: =ROUND('Cash Flow'!G42-2286.63,2) -> 0 | H50: =ROUND('Cash Flow'!H42-2828.45,2) -> 0 | I50: 0.02 | J50: =IF(AND(ABS(D50)<=I50,ABS(E50)<=I50,ABS(F50)<=I50,ABS(G50)<=I50,ABS(H50)<=I50),"OK","Review") -> OK
C51: Investing cash flow vs reported | D51: =ROUND('Cash Flow'!D57-(-558.14),2) -> 0 | E51: =ROUND('Cash Flow'!E57-(-898.95),2) -> 0 | F51: =ROUND('Cash Flow'!F57-(-1769.29),2) -> 0 | G51: =ROUND('Cash Flow'!G57-(-1541.59),2) -> 0 | H51: =ROUND('Cash Flow'!H57-(-1224.1),2) -> 0 | I51: 0.02 | J51: =IF(AND(ABS(D51)<=I51,ABS(E51)<=I51,ABS(F51)<=I51,ABS(G51)<=I51,ABS(H51)<=I51),"OK","Review") -> OK
C52: Financing cash flow vs reported | D52: =ROUND('Cash Flow'!D70-(-467.96),2) -> 0 | E52: =ROUND('Cash Flow'!E70-(-656.43),2) -> 0 | F52: =ROUND('Cash Flow'!F70-(-742.45),2) -> 0 | G52: =ROUND('Cash Flow'!G70-(-917.94),2) -> 0 | H52: =ROUND('Cash Flow'!H70-(-1672.77),2) -> 0 | I52: 0.02 | J52: =IF(AND(ABS(D52)<=I52,ABS(E52)<=I52,ABS(F52)<=I52,ABS(G52)<=I52,ABS(H52)<=I52),"OK","Review") -> OK
C53: Net cash change vs reported | D53: =ROUND('Cash Flow'!D73-(-70.73),2) -> 0 | E53: =ROUND('Cash Flow'!E73-2.19,2) -> 0 | F53: =ROUND('Cash Flow'!F73-212.29,2) -> -0.01 | G53: =ROUND('Cash Flow'!G73-(-172.9),2) -> 0 | H53: =ROUND('Cash Flow'!H73-(-68.42),2) -> 0 | I53: 0.02 | J53: =IF(AND(ABS(D53)<=I53,ABS(E53)<=I53,ABS(F53)<=I53,ABS(G53)<=I53,ABS(H53)<=I53),"OK","Review") -> OK
C54: Note 15 cash-credit and bank-overdraft reconciliation | D54: =ROUND('Balance Sheet'!D25-'Cash Flow'!D79-95.6,2) -> 0 | E54: =ROUND('Balance Sheet'!E25-'Cash Flow'!E79-52.05,2) -> 0 | F54: =ROUND('Balance Sheet'!F25-'Cash Flow'!F79-56.25,2) -> 0 | G54: =ROUND('Balance Sheet'!G25-'Cash Flow'!G79-37.32,2) -> 0 | H54: =ROUND('Balance Sheet'!H25-'Cash Flow'!H79-14.29,2) -> 0 | I54: 0.02 | J54: =IF(AND(ABS(D54)<=I54,ABS(E54)<=I54,ABS(F54)<=I54,ABS(G54)<=I54,ABS(H54)<=I54),"OK","Review") -> OK | K54: Balance-sheet cash less Note 15 cash equals reported overdrafts included in current borrowings
C55: Revenue-note bridge vs P&L revenue | D55: =ROUND(Revenue!D11-'P&L'!D7,2) -> 0 | E55: =ROUND(Revenue!E11-'P&L'!E7,2) -> 0 | F55: =ROUND(Revenue!F11-'P&L'!F7,2) -> 0 | G55: =ROUND(Revenue!G11-'P&L'!G7,2) -> 0 | H55: =ROUND(Revenue!H11-'P&L'!H7,2) -> 0 | I55: 0.02 | J55: =IF(AND(ABS(D55)<=I55,ABS(E55)<=I55,ABS(F55)<=I55,ABS(G55)<=I55,ABS(H55)<=I55),"OK","Review") -> OK | K55: Revenue-note components sum to reported revenue from operations in every year
C56: Consolidated segment net revenue vs P&L revenue | D56: =ROUND(Segment!D10-'P&L'!D7,2) -> 0 | E56: =ROUND(Segment!E10-'P&L'!E7,2) -> 0 | F56: =ROUND(Segment!F10-'P&L'!F7,2) -> 0.01 | G56: =ROUND(Segment!G10-'P&L'!G7,2) -> 0 | H56: =ROUND(Segment!H10-'P&L'!H7,2) -> 0 | I56: 0.02 | J56: =IF(AND(ABS(D56)<=I56,ABS(E56)<=I56,ABS(F56)<=I56,ABS(G56)<=I56,ABS(H56)<=I56),"OK","Review") -> OK | K56: FY:24 displayed segment components sum ₹0.01 crore above reported revenue due to line-item rounding; within tolerance
